[2024-05-06 05:08:16,191] {taskinstance.py:1179} INFO - Dependencies all met for <TaskInstance: Lead_Scoring_Data_Engineering_Pipeline.mapping_interactions manual__2024-05-06T05:07:23.797062+00:00 [queued]>
[2024-05-06 05:08:16,196] {taskinstance.py:1179} INFO - Dependencies all met for <TaskInstance: Lead_Scoring_Data_Engineering_Pipeline.mapping_interactions manual__2024-05-06T05:07:23.797062+00:00 [queued]>
[2024-05-06 05:08:16,196] {taskinstance.py:1376} INFO - 
--------------------------------------------------------------------------------
[2024-05-06 05:08:16,196] {taskinstance.py:1377} INFO - Starting attempt 2 of 2
[2024-05-06 05:08:16,196] {taskinstance.py:1378} INFO - 
--------------------------------------------------------------------------------
[2024-05-06 05:08:16,222] {taskinstance.py:1397} INFO - Executing <Task(PythonOperator): mapping_interactions> on 2024-05-06 05:07:23.797062+00:00
[2024-05-06 05:08:16,225] {standard_task_runner.py:52} INFO - Started process 3629 to run task
[2024-05-06 05:08:16,228] {standard_task_runner.py:79} INFO - Running: ['airflow', 'tasks', 'run', 'Lead_Scoring_Data_Engineering_Pipeline', 'mapping_interactions', 'manual__2024-05-06T05:07:23.797062+00:00', '--job-id', '39', '--raw', '--subdir', 'DAGS_FOLDER/Lead_scoring_data_pipeline/.ipynb_checkpoints/lead_scoring_data_pipeline-checkpoint.py', '--cfg-path', '/tmp/tmp3dv06kkr', '--error-file', '/tmp/tmpefkv8v_c']
[2024-05-06 05:08:16,229] {standard_task_runner.py:80} INFO - Job 39: Subtask mapping_interactions
[2024-05-06 05:08:16,269] {task_command.py:371} INFO - Running <TaskInstance: Lead_Scoring_Data_Engineering_Pipeline.mapping_interactions manual__2024-05-06T05:07:23.797062+00:00 [running]> on host 9eefda8bbe39
[2024-05-06 05:08:16,310] {taskinstance.py:1589} INFO - Exporting the following env vars:
AIRFLOW_CTX_DAG_OWNER=airflow
AIRFLOW_CTX_DAG_ID=Lead_Scoring_Data_Engineering_Pipeline
AIRFLOW_CTX_TASK_ID=mapping_interactions
AIRFLOW_CTX_EXECUTION_DATE=2024-05-06T05:07:23.797062+00:00
AIRFLOW_CTX_TRY_NUMBER=2
AIRFLOW_CTX_DAG_RUN_ID=manual__2024-05-06T05:07:23.797062+00:00
[2024-05-06 05:08:16,311] {logging_mixin.py:115} INFO - saving into model_input
[2024-05-06 05:08:20,064] {taskinstance.py:1909} ERROR - Task failed with exception
Traceback (most recent call last):
  File "/opt/conda/lib/python3.8/site-packages/airflow/operators/python.py", line 171, in execute
    return_value = self.execute_callable()
  File "/opt/conda/lib/python3.8/site-packages/airflow/operators/python.py", line 189, in execute_callable
    return self.python_callable(*self.op_args, **self.op_kwargs)
  File "/home/airflow/dags/Lead_scoring_data_pipeline/utils.py", line 249, in interactions_mapping
    df_event_mapping = pd.read_csv(INTERACTION_MAPPING,index_col=[0])
  File "/opt/conda/lib/python3.8/site-packages/pandas/util/_decorators.py", line 311, in wrapper
    return func(*args, **kwargs)
  File "/opt/conda/lib/python3.8/site-packages/pandas/io/parsers/readers.py", line 680, in read_csv
    return _read(filepath_or_buffer, kwds)
  File "/opt/conda/lib/python3.8/site-packages/pandas/io/parsers/readers.py", line 575, in _read
    parser = TextFileReader(filepath_or_buffer, **kwds)
  File "/opt/conda/lib/python3.8/site-packages/pandas/io/parsers/readers.py", line 934, in __init__
    self._engine = self._make_engine(f, self.engine)
  File "/opt/conda/lib/python3.8/site-packages/pandas/io/parsers/readers.py", line 1218, in _make_engine
    self.handles = get_handle(  # type: ignore[call-overload]
  File "/opt/conda/lib/python3.8/site-packages/pandas/io/common.py", line 786, in get_handle
    handle = open(
FileNotFoundError: [Errno 2] No such file or directory: './mapping/interaction_mapping.csv'
[2024-05-06 05:08:20,068] {taskinstance.py:1415} INFO - Marking task as FAILED. dag_id=Lead_Scoring_Data_Engineering_Pipeline, task_id=mapping_interactions, execution_date=20240506T050723, start_date=20240506T050816, end_date=20240506T050820
[2024-05-06 05:08:20,102] {standard_task_runner.py:92} ERROR - Failed to execute job 39 for task mapping_interactions ([Errno 2] No such file or directory: './mapping/interaction_mapping.csv'; 3629)
[2024-05-06 05:08:20,135] {local_task_job.py:156} INFO - Task exited with return code 1
[2024-05-06 05:08:20,212] {local_task_job.py:273} INFO - 0 downstream tasks scheduled from follow-on schedule check
